pygame 2.1.2 (SDL 2.26.5, Python 3.11.2)
Hello from the pygame community. https://www.pygame.org/contribute.html
Traceback (most recent call last):
  File "/usr/lib/python3/dist-packages/gpiozero/pins/pi.py", line 411, in pin
    pin = self.pins[info]
          ~~~~~~~~~^^^^^^
KeyError: PinInfo(number=12, name='GPIO18', names=frozenset({'BOARD12', '18', 18, 'GPIO18', 'BCM18', 'WPI1', 'J8:12'}), pull='', row=6, col=2, interfaces=frozenset({'', 'spi', 'pcm', 'pwm', 'gpio', 'dpi'}))

During handling of the above exception, another exception occurred:

Traceback (most recent call last):
  File "/home/zt01/unitree_zt01/servo.py", line 6, in <module>
    servo = Servo(18)  # GPIO18 (PIN12 f√≠sico)
            ^^^^^^^^^
  File "/usr/lib/python3/dist-packages/gpiozero/devices.py", line 108, in __call__
    self = super().__call__(*args, **kwargs)
           ^^^^^^^^^^^^^^^^^^^^^^^^^^^^^^^^^
  File "/usr/lib/python3/dist-packages/gpiozero/output_devices.py", line 1503, in __init__
    pwm_device=PWMOutputDevice(
               ^^^^^^^^^^^^^^^^
  File "/usr/lib/python3/dist-packages/gpiozero/devices.py", line 108, in __call__
    self = super().__call__(*args, **kwargs)
           ^^^^^^^^^^^^^^^^^^^^^^^^^^^^^^^^^
  File "/usr/lib/python3/dist-packages/gpiozero/output_devices.py", line 392, in __init__
    super().__init__(pin, active_high=active_high, initial_value=None,
  File "/usr/lib/python3/dist-packages/gpiozero/output_devices.py", line 74, in __init__
    super().__init__(pin, pin_factory=pin_factory)
  File "/usr/lib/python3/dist-packages/gpiozero/mixins.py", line 75, in __init__
    super().__init__(*args, **kwargs)
  File "/usr/lib/python3/dist-packages/gpiozero/devices.py", line 553, in __init__
    pin = self.pin_factory.pin(pin)
          ^^^^^^^^^^^^^^^^^^^^^^^^^
  File "/usr/lib/python3/dist-packages/gpiozero/pins/pi.py", line 413, in pin
    pin = self.pin_class(self, info)
          ^^^^^^^^^^^^^^^^^^^^^^^^^^
  File "/usr/lib/python3/dist-packages/gpiozero/pins/lgpio.py", line 126, in __init__
    lgpio.gpio_claim_input(
  File "/usr/lib/python3/dist-packages/lgpio.py", line 755, in gpio_claim_input
    return _u2i(_lgpio._gpio_claim_input(handle&0xffff, lFlags, gpio))
           ^^^^^^^^^^^^^^^^^^^^^^^^^^^^^^^^^^^^^^^^^^^^^^^^^^^^^^^^^^^
  File "/usr/lib/python3/dist-packages/lgpio.py", line 458, in _u2i
    raise error(error_text(v))
lgpio.error: 'GPIO busy'
